Workbook

Sheet 表紙
O8: LMS学習管理システム
O9: 体験型Java研修
S11: 画面レイアウト設計書
X15: ="第"&TEXT(MAX(更新履歴!A8:I167),"#0.0")&"版" -> 第1.0版 | AA15: =MAX(更新履歴!J8:Q31) -> 44265
U18: 作成者 | Z18: 審査者 | AE18: 承認者
U19: 臼井

Sheet 更新履歴
A1: プロジェクト名 | J1: システム名 | R1: 画面レイアウト設計書 | AJ1: 作成者 | AO1: 作成日 | AT1: 更新者 | AY1: 更新日
A2: =表紙!O9 -> 体験型Java研修 | J2: =表紙!O8 -> LMS学習管理システム | R2: 更新履歴 | AJ2: 臼井 | AO2: 44265
A5: バージョン | J5: 日付 | R5: 章番号 | V5: 内容 | AT5: 作成者 / 更新者
A8: 1 | J8: 44265 | R8: 全て | V8: 新規作成 | AT8: 臼井

Sheet 画面遷移図_受講生
A1: 受講生

Sheet ログイン_画面詳細
A1: プロジェクト名 | J1: システム名 | R1: =[1]表紙!O11 -> 画面レイアウト設計書 | AJ1: 作成者 | AO1: 作成日 | AT1: 更新者 | AY1: 更新日
A2: =[1]表紙!O9 -> 体験型Java研修 | J2: =[1]表紙!O8 -> LMS学習管理システム | R2: =[1]表紙!S10 -> 共通部品 | AJ2: 臼井 | AO2: 44265 | AT2: 臼井 | AY2: 44349
B5: 画面イメージ
B36: 画面表示項目
B37: No | D37: 項目名 | N37: データ元 | AD37: 備考 | AX37: 権限ごとの 表示可否
N38: テーブル名 | V38: フィールド | AX38: 受 | AY38: 講 | AZ38: 企 | BA38: 管 | BB38: 育
B39: 1 | D39: ログインID | N39: - | V39: -
B40: 2 | D40: パスワード | N40: - | V40: -
B41: 3 | D41: 『ログイン』ボタン | N41: - | V41: -
B42: 4 | D42: 『パスワードを忘れた方はこちら』リンク | N42: - | V42: -
B43: 5 | D43: お知らせ | N43: t_info | V43: content | AD43: 最新１件のみ表示
B44: 6 | D44: マニュアルダウンロード | N44: - | V44: -
B45: 7 | D45: よくある質問 | N45: - | V45: -
B48: 入力パラメータ
B49: No | D49: 項目名 | N49: 物理名 | U49: コントロール | AB49: FORMクラスの入力チェック | AD49: 桁数 | AF49: 最大値 | AH49: 最小値 | AJ49: その他チェック | AN49: 送信 方法 | AP49: 備考
B50: No | D50: 項目名 | N50: 物理名 | U50: コントロール | AB50: 必須 | AD50: 桁数 | AF50: 最大値 | AH50: 最小値 | AJ50: その他 | AN50: 方法 | AP50: 備考
B51: 『ログイン』ボタン押下
B52: 1 | D52: ログインID | N52: loginId | U52: text | AB52: - | AD52: - | AF52: - | AH52: - | AJ52: - | AN52: POST
B53: 2 | D53: パスワード | N53: password | U53: password | AB53: - | AD53: - | AF53: - | AH53: - | AJ53: - | AN53: POST

Sheet ログイン_イベント処理
A1: プロジェクト名 | J1: システム名 | R1: 画面レイアウト設計書 | AJ1: 作成者 | AO1: 作成日 | AT1: 更新者 | AY1: 更新日
A2: =表紙!O9 -> 体験型Java研修 | J2: =表紙!O8 -> LMS学習管理システム | R2: {=MID(CELL("filename",A1),FIND("]",CELL("filename",A1))+1,FIND("_",MID(CELL("filename",A1),FIND("]",CELL("filename",A1))+2,30)))} -> ログイン | AJ2: 臼井 | AO2: 44265
B5: イベント処理
B7: No | D7: イベント名 | M7: イベント内容 | AV7: 備考
B8: 1 | D8: 初期表示 | M8: ①．ログイン画面へ遷移
D10: コントローラー：/
B11: 2 | D11: 『ログイン』ボタン押下 | M11: ①．パラメータチェック
D13: コントローラー： | O13: Ⅰ．ログインボタンが押された場合、以下の処理を行う
D14: /login
O15: Ⅱ．入力チェック
Q17: ａ．ログインIDおよびパスワードが入力されていない場合、エラーメッセージ設定し、ログイン画面へ遷移
S19: メッセージID | W19: required
S20: パラメータ | W20: ログインID or パスワード
O22: Ⅲ．存在チェック
Q24: ａ．下記APIを呼び出し、ユーザチェックを行う
S26: API | W26: ログインAPI．ログイン
S27: パラメータ | W27: ログインID、パスワード
Q29: ｂ．ａの結果で文字列が入っていた場合、エラーメッセージをログ出力し、ログイン画面へ遷移
M33: ②．コース詳細画面へ遷移
B36: 3 | D36: 『パスワードを忘れた方はこちら』リンク押下 | M36: ①.パスワードリセット画面へ遷移
D38: コントローラー：
D39: /password/resetPassword

Sheet コース詳細_画面詳細
A1: プロジェクト名 | J1: システム名 | R1: 画面レイアウト設計書 | AJ1: 作成者 | AO1: 作成日 | AT1: 更新者 | AY1: 更新日
A2: =表紙!O9 -> 体験型Java研修 | J2: =表紙!O8 -> LMS学習管理システム | R2: {=MID(CELL("filename",A1),FIND("]",CELL("filename",A1))+1,FIND("_",MID(CELL("filename",A1),FIND("]",CELL("filename",A1))+2,30)))} -> コース詳細 | AJ2: 臼井 | AO2: 44265
B5: 画面イメージ
B33: 画面表示項目
B34: No | D34: 項目名 | N34: データ元 | AD34: 備考 | AX34: 権限ごとの 表示可否
N35: テーブル名 | V35: フィールド | AX35: 受 | AY35: 講 | AZ35: 企 | BA35: 管 | BB35: 育
B36: 1 | D36: パンくずリスト | N36: - | V36: - | AD36: 「コース詳細」と表示 | AX36: ○ | AY36: ○
B37: コース情報
B38: 2 | D38: コース名 | N38: m_course | V38: course_name | AX38: ○ | AY38: ○
B39: 3 | D39: 開講日 | N39: m_course | V39: open_time | AD39: yyyy年MM月dd日 | AX39: ○ | AY39: ○
B40: 4 | D40: 閉講日 | N40: m_course | V40: close_time | AD40: yyyy年MM月dd日 | AX40: ○ | AY40: ○
B41: セクション情報 （※1）
B42: 5 | D42: カテゴリー名 | N42: m_category | V42: category_name | AX42: ○ | AY42: ○
B43: 6 | D43: 日付 | N43: m_section | V43: date | AD43: yyy年MM月dd日(E) | AX43: ○ | AY43: ○ | BD43: Task.14
B44: 7 | D44: セクション名 | N44: m_section | V44: section_name | AX44: ○ | AY44: ○
B45: 8 | D45: レポート提出状況 | N45: - | V45: - | AD45: ・当該セクションのレポートが提出済の場合：提出済み ・当該セクションのレポートが未提出の場合：未提出 | AX45: ○ | AY45: ○ | BD45: Task.15
B46: 9 | D46: 試験有無 | N46: - | V46: - | AD46: ・当該セクションに試験がある場合：試験有 ・当該セクションに試験がない場合：試験無 | AX46: ○ | AY46: ○ | BD46: Task.16
B47: 10 | D47: 『詳細』ボタン | N47: - | V47: - | AX47: ○ | AY47: ○
B48: （※1） | D48: 日付が現在日付と同じであれば背景色を変える（#d9edf7） | BD48: Task.14
B50: 入力パラメータ
B51: No | D51: 項目名 | N51: 物理名 | U51: コントロール | AB51: FORMクラスの入力チェック | AD51: 桁数 | AF51: 最大値 | AH51: 最小値 | AJ51: その他チェック | AN51: 送信 方法 | AP51: 備考
B52: No | D52: 項目名 | N52: 物理名 | U52: コントロール | AB52: 必須 | AD52: 桁数 | AF52: 最大値 | AH52: 最小値 | AJ52: その他 | AN52: 方法 | AP52: 備考
B53: 『詳細』ボタン押下
B54: 1 | D54: コースID | N54: courseId | U54: hidden | AB54: - | AD54: - | AF54: - | AH54: - | AJ54: - | AN54: POST
B55: 2 | D55: セクションID | N55: sectionId | U55: hidden | AB55: - | AD55: - | AF55: - | AH55: - | AJ55: - | AN55: POST

Sheet コース詳細_イベント処理
A1: プロジェクト名 | J1: システム名 | R1: 画面レイアウト設計書 | AJ1: 作成者 | AO1: 作成日 | AT1: 更新者 | AY1: 更新日
A2: =表紙!O9 -> 体験型Java研修 | J2: =表紙!O8 -> LMS学習管理システム | R2: {=MID(CELL("filename",A1),FIND("]",CELL("filename",A1))+1,FIND("_",MID(CELL("filename",A1),FIND("]",CELL("filename",A1))+2,30)))} -> コース詳細 | AJ2: 臼井 | AO2: 44265
B5: イベント処理
B7: No | D7: イベント名 | M7: イベント内容 | AV7: 備考
B8: 1 | D8: 初期表示 | M8: ①．パラメータチェック
D10: コントローラー： | O10: Ⅰ．ログインユーザーが受講生権限の場合、以下の処理を行う
D11: /course/detail
O12: Ⅱ．数値チェック
Q14: ａ．ログイン情報ＤＴＯ．コースＩＤが数値ではない場合、エラーメッセージをログ出力し、不正アクセス画面へ遷移
S16: メッセージID | W16: integer
S17: パラメータ | W17: courseId
O19: Ⅲ．コース取得チェック
Q21: ａ．下記APIを呼び出し、コース数を取得
S23: API | W23: コースAPI．コース数取得
S24: パラメータ | W24: ログイン情報DTO．コースID
Q26: ｂ．ａの結果が0件だった場合、エラーメッセージをログ出力し、不正アクセス画面へ遷移
S28: メッセージID | W28: alreadydelete
S29: パラメータ | W29: sectionId
M31: ②．コース詳細取得
O33: Ⅰ．下記APIを呼び出し、コース詳細を取得
Q35: API | U35: コースAPI．コース詳細取得
Q36: パラメータ | U36: ログイン情報DTO．コースID
U37: 削除フラグ（0）
O40: Ⅱ．当日フラグの設定 | AV40: ※画面上、当日のセクションの | BD40: Task.14
AV41: 背景色を変更するため
P42: a．現在日付を取得
P44: ｂ．コース詳細DTO．コース情報サービス カテゴリDTOリスト．コース情報サービス セクションDTOリストの日付と
Q45: 現在日付が一致する場合、
Q46: コース詳細DTO．コース情報サービス カテゴリDTOリスト．コース情報サービス セクションDTOリスト．当日フラグに
Q47: trueを設定。上記以外はfalseを設定
M50: ④．コース詳細画面へ遷移
B53: 2 | D53: 『詳細』ボタン押下 | M53: ①.セクション詳細画面へ遷移
D55: コントローラー：
D56: /section/detail

Sheet セクション詳細_画面詳細
A1: プロジェクト名 | J1: システム名 | R1: 画面レイアウト設計書 | AJ1: 作成者 | AO1: 作成日 | AT1: 更新者 | AY1: 更新日
A2: =表紙!O9 -> 体験型Java研修 | J2: =表紙!O8 -> LMS学習管理システム | R2: {=MID(CELL("filename",A1),FIND("]",CELL("filename",A1))+1,FIND("_",MID(CELL("filename",A1),FIND("]",CELL("filename",A1))+2,30)))} -> セクション詳細 | AJ2: 臼井 | AO2: 44265
B5: 画面イメージ
B39: 試験が未公開の場合
B49: 画面表示項目
B50: No | D50: 項目名 | N50: データ元 | AD50: 備考 | AX50: 権限ごとの 表示可否
N51: テーブル名 | V51: フィールド | AX51: 受 | AY51: 講 | AZ51: 企 | BA51: 管 | BB51: 育
B52: 1 | D52: パンくずリスト | N52: - | V52: - | AD52: 「（『コース詳細』リンク） / セクション詳細」と表示 | AX52: ○ | AY52: ○
B53: タイトル
B54: 2 | D54: セクション名 | N54: m_section | V54: section_name | AX54: ○ | AY54: ○
B55: 3 | D55: 日付 | N55: m_section | V55: date | AD55: 「yyyy年M月d日」と表示 | AX55: ○ | AY55: ○
B56: 本日の内容
B57: 4 | D57: 概要 | N57: m_section | V57: section_description | AX57: ○ | AY57: ○
B58: 本日の資料 ※未登録の場合（当日新しく配布する資料がない場合）は非表示
B59: 5 | D59: 資料 | N59: m_file | V59: file_name | AD59: 『ファイル名』リンクを表示 ファイル名に「movieId=(動画判別名称)」が存在する場合は、#(リンクIDと動画名称の区切り文字)以降をファイル名として表示する | AX59: ○ | AY59: ○
B60: 本日の試験 ※未登録の場合は非表示
B61: 5 | D61: 試験（＋公開日時） | N61: m_exam | V61: exam_name | AD61: ・試験が未公開の場合 ： 「試験名(HH:mm公開)」と表示 ・試験が公開済の場合 ： 「試験名」と表示 | AX61: ○ | AY61: -
B62: 6 | N62: t_exam_section | V62: public_data | AX62: ○ | AY62: -
B63: 7 | D63: 詳細 | N63: - | V63: - | AD63: ・試験が未公開の場合 ： 『詳細』ボタン非表示 ・試験が公開済の場合 ： 『詳細』ボタン表示 | AX63: ○ | AY63: -
B64: 8 | D64: 実施 | N64: - | V64: - | AD64: ・試験が未実施の場合 ： 何も表示しない ・試験が実施済の場合 ： 「済」と表示 | AX64: ○ | AY64: - | BD64: Task.17
B65: 本日のレポート ※未登録の場合は非表示
B66: 9 | D66: レポート | N66: m_daily_report | V66: report_name | AD66: ・レポート提出済の場合 ： 『提出済み｛レポート名｝を確認する』ボタンを表示 ・レポート未提出の場合 ： 『｛レポート名｝を提出する』ボタンを表示 | AX66: ○ | AY66: -
B67: フッター
B68: 10 | D68: 『戻る』ボタン | N68: - | V68: - | AD68: 押下後、遷移元画面へ遷移 | AX68: ○ | AY68: - | BD68: Task.17
B71: 入力パラメータ
B72: No | D72: 項目名 | N72: 物理名 | U72: コントロール | AB72: FORMクラスの入力チェック | AD72: 桁数 | AF72: 最大値 | AH72: 最小値 | AJ72: その他チェック | AN72: 送信 方法 | AP72: 備考
B73: No | D73: 項目名 | N73: 物理名 | U73: コントロール | AB73: 必須 | AD73: 桁数 | AF73: 最大値 | AH73: 最小値 | AJ73: その他 | AN73: 方法 | AP73: 備考
B74: 『コース詳細』リンク押下
B75: - | D75: - | N75: なし | U75: - | AB75: - | AD75: - | AF75: - | AH75: - | AJ75: - | AN75: -
B76: 『ファイル名』リンク押下
B77: 1 | D77: ファイルID | N77: fileId | U77: hidden | AB77: - | AD77: - | AF77: - | AH77: - | AJ77: - | AN77: -
B78: 2 | D78: ファイル名 | N78: fileName | U78: hidden | AB78: - | AD78: - | AF78: - | AH78: - | AJ78: - | AN78: -
B79: 『詳細』ボタン押下
B80: 1 | D80: 試験ID | N80: examId | U80: hidden | AB80: - | AD80: - | AF80: - | AH80: - | AJ80: - | AN80: POST
B81: 2 | D81: セクションID | N81: sectionId | U81: hidden | AB81: - | AD81: - | AF81: - | AH81: - | AJ81: - | AN81: POST
B82: 3 | D82: 試験・セクションID | N82: examSectionId | U82: hidden | AB82: - | AD82: - | AF82: - | AH82: - | AJ82: - | AN82: POST
B83: 『提出済み｛レポート名｝を確認する』ボタン押下
B84: 4 | D84: 日報ID | N84: dailyReportId | U84: hidden | AB84: - | AD84: - | AF84: - | AH84: - | AJ84: - | AN84: POST
B85: 5 | D85: セクションID | N85: sectionId | U85: hidden | AB85: - | AD85: - | AF85: - | AH85: - | AJ85: - | AN85: POST
B86: 6 | D86: コースID | N86: courseId | U86: hidden | AB86: - | AD86: - | AF86: - | AH86: - | AJ86: - | AN86: POST
...

Sheet セクション詳細_イベント処理
A1: プロジェクト名 | J1: システム名 | R1: 画面レイアウト設計書 | AJ1: 作成者 | AO1: 作成日 | AT1: 更新者 | AY1: 更新日
A2: =表紙!O9 -> 体験型Java研修 | J2: =表紙!O8 -> LMS学習管理システム | R2: {=MID(CELL("filename",A1),FIND("]",CELL("filename",A1))+1,FIND("_",MID(CELL("filename",A1),FIND("]",CELL("filename",A1))+2,30)))} -> セクション詳細 | AJ2: 臼井 | AO2: 44265
B5: イベント処理
B7: No | D7: イベント名 | M7: イベント内容 | AV7: 備考
B8: 1 | D8: 初期表示 | M8: ①セクションID、セクション情報チェック
O10: Ⅰ．数値チェック
D11: コントローラー： | Q11: a．入力パラメータ．セクションIDが数値じゃない場合、下記エラーメッセージをログに出力し、エラー画面へ遷移
D12: /section/detail
S13: メッセージID | W13: integer
S14: パラメータ | W14: sectionId
O16: Ⅱ．セクションマスタの件数の取得
Q18: Ⅰ．下記APIを呼び出し、セクションマスタの件数を取得
S20: API | W20: セクションAPI．セクション件数取得
S21: パラメータ | W21: 入力パラメータ．セクションID
Q23: Ⅱ．Ⅰで取得した件数が0だった場合、下記エラーメッセージをログに出力し、エラー画面へ遷移
S25: メッセージID | W25: alreadydelete
S26: パラメータ | W26: sectionId
M29: ③．セクション情報の取得
O30: Ⅰ．セクションサービスDTOの取得
P31: a．下記APIを呼び出し、セクションサービスDTOを取得
R33: API | V33: セクションAPI．セクションサービスDTO取得
R34: パラメータ | V34: 入力パラメータ．セクションID
V35: ログイン情報DTO．企業アカウントID
V36: ログイン情報DTO．LMSユーザID
R37: パラメータ | V37: 削除フラグ(0)
O39: Ⅱ．セクション・日報紐付け情報の取得
P40: a．下記APIを呼び出し、セクションサービスレポートDTO取得
R42: API | V42: セクション・日報紐付けAPI．セクションサービスレポートDTO取得
R43: パラメータ | V43: 入力パラメータ．セクションID
V44: ログイン情報DTO．LMSユーザID
R45: パラメータ | V45: 削除フラグ(0)
P47: b．Ⅱ-aのセクションサービスレポートDTOがnullでない場合、Ⅰ-aセクションサービスDTOに追加
P49: ｃ．下記通り、セクション詳細情報DTOに設定
R51: セクションサービスDTO．レポートDTOリスト | AF51: ＝ セクションサービスレポートDTO
R52: セクションサービスDTO．ファイルＤＴＯリスト | AF52: ＝ ファイルＩＤ（ハッシュ化済）
R53: セクションサービスDTO．ファイルサイズ | AF53: ＝ （成果物アップロードファイルの最大値 ）
M56: ⑤．セクション詳細画面へ遷移
B59: 2 | D59: 『コース詳細』リンク押下 | M59: ①.コース詳細画面へ遷移
D61: コントローラー：
D62: /course/detail
...

Sheet レポート登録_画面詳細
A1: プロジェクト名 | J1: システム名 | R1: 画面レイアウト設計書 | AJ1: 作成者 | AO1: 作成日 | AT1: 更新者 | AY1: 更新日
A2: =表紙!O9 -> 体験型Java研修 | J2: =表紙!O8 -> LMS学習管理システム | R2: {=MID(CELL("filename",A1),FIND("]",CELL("filename",A1))+1,FIND("_",MID(CELL("filename",A1),FIND("]",CELL("filename",A1))+2,30)))} -> レポート登録 | AJ2: 臼井 | AO2: 44265
B5: 画面イメージ
C7: 日報の場合
C27: 週報/月報の場合
B67: エラーメッセージ表示イメージ
B79: 画面表示項目
B80: No | D80: 項目名 | N80: データ元 | AD80: 備考 | AX80: 権限ごとの 表示可否
N81: テーブル名 | V81: フィールド | AX81: 受 | AY81: 講 | AZ81: 企 | BA81: 管 | BB81: 育
B82: 1 | D82: レポート名 | N82: m_daily_report | V82: report_name | AX82: ○
B83: 2 | D83: 日付 | N83: m_section | V83: date | AD83: yyyy年M月d日 | AX83: ○
B84: 学習理解度 ※未登録の場合は非表示（学習理解度フラグが1の場合）
B85: 3 | D85: 学習項目 | N85: t_intelligibility | V85: field_name | AD85: 理解度テーブル．学習理解度項目数に応じて学習理解度の行を追加 | AX85: ○
B86: 4 | D86: 理解度 | N86: t_intelligibility | V86: field_value | AD86: 選択肢は理解度テーブル．学習理解度数を参照 例）学習理解度数が3である場合、選択肢が1～3となる | AX86: ○
B87: 報告レポート
B88: 5 | D88: 項目名 | N88: m_daily_report_detail | V88: field_name | AX88: ○
B89: 6 | D89: 内容 | N89: t_daily_report_submit_detail | V89: content | AD89: ・入力チェックが1場合は、［必須］を表示 ・型が数値の場合は、プレースホルダーに 「例） 半角数値で、｛範囲from｝～｛範囲to｝の範囲で入力してください。」と表示 ※型の種類： 数値(コード値：0) 文字列(コード値：1) | AX89: ○
B90: 7 | N90: m_daily_report_detail | V90: required_flg | AX90: ○
B91: 8 | N91: m_daily_report_detail | V91: input_type | AX91: ○
B92: 9 | N92: m_daily_report_detail | V92: range_from | AX92: ○
B93: 10 | N93: m_daily_report_detail | V93: range_to | AX93: ○
B94: 提出ボタン
B95: 11 | D95: 『提出する』ボタン | N95: - | V95: - | AX95: ○
B96: 戻るボタン
B97: 12 | D97: 『戻る』ボタン | N97: - | V97: - | AX97: ○
B100: 入力パラメータ
B101: No | D101: 項目名 | N101: 物理名 | U101: コントロール | AB101: FORMクラスの入力チェック | AD101: 桁数 | AF101: 最大値 | AH101: 最小値 | AJ101: その他チェック | AN101: 送信 方法 | AP101: 備考
B102: No | D102: 項目名 | N102: 物理名 | U102: コントロール | AB102: 必須 | AD102: 桁数 | AF102: 最大値 | AH102: 最小値 | AJ102: その他 | AN102: 方法 | AP102: 備考
B103: 『提出する』ボタン押下
B104: 1 | D104: 学習項目 | N104: intFieldName[n] | U104: テキストボックス | AB104: - | AD104: - | AF104: - | AH104: - | AJ104: - | AN104: POST
B105: 2 | D105: 理解度 | N105: intFieldValue[n] | U105: セレクトボックス | AB105: - | AD105: - | AF105: - | AH105: - | AJ105: - | AN105: POST
B106: 3 | D106: 報告レポート項目 | N106: fieldName[n] | U106: hidden | AB106: - | AD106: - | AF106: - | AH106: - | AJ106: - | AN106: POST
B107: 4 | D107: 報告レポート内容 | N107: content[n] | U107: テキストボックス | AB107: - | AD107: - | AF107: - | AH107: - | AJ107: - | AN107: POST
B108: 5 | D108: 入力チェック | N108: requiredFlg[n] | U108: hidden | AB108: - | AD108: - | AF108: - | AH108: - | AJ108: - | AN108: POST
B109: 6 | D109: 型 | N109: inputType[n] | U109: hidden | AB109: - | AD109: - | AF109: - | AH109: - | AJ109: - | AN109: POST
B110: 7 | D110: 範囲from | N110: rangeFrom[n] | U110: hidden | AB110: - | AD110: - | AF110: - | AH110: - | AJ110: - | AN110: POST
B111: 8 | D111: 範囲to | N111: rangeTo[n] | U111: hidden | AB111: - | AD111: - | AF111: - | AH111: - | AJ111: - | AN111: POST
B112: 9 | D112: 日報ID | N112: dailyReportId | U112: hidden | AB112: - | AD112: - | AF112: - | AH112: - | AJ112: - | AN112: POST
B113: 10 | D113: セクションID | N113: sectionId | U113: hidden | AB113: - | AD113: - | AF113: - | AH113: - | AJ113: - | AN113: POST
B114: 11 | D114: コースID | N114: courseId | U114: hidden | AB114: - | AD114: - | AF114: - | AH114: - | AJ114: - | AN114: POST
...

Sheet レポート登録_イベント処理
A1: プロジェクト名 | J1: システム名 | R1: 画面レイアウト設計書 | AJ1: 作成者 | AO1: 作成日 | AT1: 更新者 | AY1: 更新日
A2: =表紙!O9 -> 体験型Java研修 | J2: =表紙!O8 -> LMS学習管理システム | R2: {=MID(CELL("filename",A1),FIND("]",CELL("filename",A1))+1,FIND("_",MID(CELL("filename",A1),FIND("]",CELL("filename",A1))+2,30)))} -> レポート登録 | AJ2: 臼井 | AO2: 44265
B5: イベント処理
B7: No | D7: イベント名 | M7: イベント内容 | AV7: 備考
B8: 1 | D8: 初期表示 | M8: ①．レポートDTOの取得
D10: コントローラー： | O10: Ⅰ．入力パラメータ．日報提出IDが空白以外の場合、下記APIを呼び出し、レポートDTOを取得
D11: /report/regist
Q12: API | U12: 日報提出API．レポートDTO取得
Q13: パラメータ | U13: 入力パラメータ．日報提出ID
O15: Ⅱ．入力パラメータ．日報提出IDがＮＵＬＬの場合
P17: a．入力パラメータ．日付をフォーマットし、実在日時チェックを行う。
P19: ｂ．下記APIを呼び出し、レポートDTOを取得
Q21: API | U21: コース・日報紐付けAPI．レポートDTO取得
Q22: パラメータ | U22: 入力パラメータ．日報ID
Q23: パラメータ | U23: ログイン情報DTO．コースID | AF23: ※
U24: ログイン情報DTO．企業アカウントID | AF24: ※
U25: ログイン情報DTO．LMSユーザID | AF25: ※
U26: 削除フラグ（0）
U27: 入力パラメータ．日付
Q28: ※ログインユーザーが受講生権限以外の場合、ログイン情報DTOではなく、入力パラメータから取得
P30: ｃ．ｂで取得できなかった場合、下記APIを呼び出し、レポートDTOを取得
Q32: API | U32: セクション・日報紐付けAPI．レポートDTO取得
Q33: パラメータ | U33: 入力パラメータ．日報ID
Q34: パラメータ | U34: 入力パラメータ．セクションID
U35: ログイン情報DTO．企業アカウントID
U36: ログイン情報DTO．LMSユーザID
U37: 削除フラグ（0）
U38: 入力パラメータ．日付
Q39: ※ログインユーザーが受講生権限以外の場合、ログイン情報DTOではなく、入力パラメータから取得
O41: Ⅲ．ⅠまたはⅡで取得したDTOを日報フォームに詰め替える。
M44: ②．レポート登録画面へ遷移
B47: 2 | D47: 『提出する』ボタン押下 | M47: ①．入力チェック | BC47: Task.18
D49: コントローラー： | O49: Ⅰ．入力パラメータ．学習項目名[i]が100文字以上ある場合、下記エラーメッセージを設定
Q51: メッセージID | U51: maxlength
Q52: パラメータ | U52: intFieldName | Y52: ※学習項目[n]
D54: /report/complete
O55: Ⅱ．入力パラメータ．学習項目[n]か理解度[n]どちらか片方のみに値がある場合、下記エラーメッセージを設定 | AV55: ※学習項目、理解度の
AV56: どちらも値がある
Q57: メッセージID | U57: required.when | AV57: or どちらも値がない
Q58: パラメータ | U58: intFieldValue | Y58: ※学習項目[n]の方に値がない場合 | AV58: 場合はエラーなし
...

Sheet 404画面_画面詳細
A1: プロジェクト名 | J1: システム名 | R1: 画面レイアウト設計書 | AJ1: 作成者 | AO1: 作成日 | AT1: 更新者 | AY1: 更新日
A2: =表紙!O9 -> 体験型Java研修 | J2: =表紙!O8 -> LMS学習管理システム | R2: {=MID(CELL("filename",A1),FIND("]",CELL("filename",A1))+1,FIND("_",MID(CELL("filename",A1),FIND("]",CELL("filename",A1))+2,30)))} -> 404画面 | AJ2: 臼井 | AO2: 44265
B5: 画面イメージ
B28: 画面表示項目
B29: No | D29: 項目名 | N29: データ元 | AD29: 備考 | AX29: 権限ごとの 表示可否
N30: テーブル名 | V30: フィールド | AX30: 受 | AY30: 講 | AZ30: 企 | BA30: 管 | BB30: 育
B31: 1 | D31: エラーメッセージ | N31: - | V31: - | AD31: 「指定したページは見つかりません。」を表示 | AX31: ○ | AY31: ○
B32: 2 | D32: 『戻る』ボタン | N32: - | V32: - | AX32: ○ | AY32: ○ | BD32: Task.09
B35: 入力パラメータ
B36: No | D36: 項目名 | N36: 物理名 | U36: コントロール | AB36: FORMクラスの入力チェック | AD36: 桁数 | AF36: 最大値 | AH36: 最小値 | AJ36: その他チェック | AN36: 送信 方法 | AP36: 備考
B37: No | D37: 項目名 | N37: 物理名 | U37: コントロール | AB37: 必須 | AD37: 桁数 | AF37: 最大値 | AH37: 最小値 | AJ37: その他 | AN37: 方法 | AP37: 備考
B38: 『戻る』ボタン
B39: - | D39: なし | N39: - | U39: - | AB39: - | AD39: - | AF39: - | AH39: - | AJ39: - | AN39: - | BD39: Task.09

Sheet 404画面_イベント処理
A1: プロジェクト名 | J1: システム名 | R1: 画面レイアウト設計書 | AJ1: 作成者 | AO1: 作成日 | AT1: 更新者 | AY1: 更新日
A2: =表紙!O9 -> 体験型Java研修 | J2: =表紙!O8 -> LMS学習管理システム | R2: {=MID(CELL("filename",A1),FIND("]",CELL("filename",A1))+1,FIND("_",MID(CELL("filename",A1),FIND("]",CELL("filename",A1))+2,30)))} -> 404画面 | AJ2: 臼井 | AO2: 44265
B5: イベント処理
B7: No | D7: イベント名 | M7: イベント内容 | AV7: 備考
B8: 1 | D8: 初期表示 | M8: ①．404画面へ遷移
D10: コントローラー：
D11: なし
B13: 2 | D13: 『戻る』ボタン | M13: ①．ログイン画面へ遷移 | AV13: Task.09
N14: ※ログイン済の場合、自動で権限によって異なるトップ画面へリダイレクトされる
D15: コントローラー： | O15: 例）受講生の場合、コース詳細画面
D16: /

Sheet エラー画面_画面詳細
A1: プロジェクト名 | J1: システム名 | R1: 画面レイアウト設計書 | AJ1: 作成者 | AO1: 作成日 | AT1: 更新者 | AY1: 更新日
A2: =表紙!O9 -> 体験型Java研修 | J2: =表紙!O8 -> LMS学習管理システム | R2: {=MID(CELL("filename",A1),FIND("]",CELL("filename",A1))+1,FIND("_",MID(CELL("filename",A1),FIND("]",CELL("filename",A1))+2,30)))} -> エラー画面 | AJ2: 臼井 | AO2: 44265
B5: 画面イメージ
B29: 画面表示項目
B30: No | D30: 項目名 | N30: データ元 | AD30: 備考 | AX30: 権限ごとの 表示可否
N31: テーブル名 | V31: フィールド | AX31: 受 | AY31: 講 | AZ31: 企 | BA31: 管 | BB31: 育
B32: 1 | D32: エラーメッセージ | N32: - | V32: - | AD32: 「エラーが発生しました。」を表示 | AX32: ○ | AY32: ○
B33: 2 | D33: 『戻る』ボタン | N33: - | V33: - | AX33: ○ | AY33: ○ | BD33: Task.09
B36: 入力パラメータ
B37: No | D37: 項目名 | N37: 物理名 | U37: コントロール | AB37: FORMクラスの入力チェック | AD37: 桁数 | AF37: 最大値 | AH37: 最小値 | AJ37: その他チェック | AN37: 送信 方法 | AP37: 備考
B38: No | D38: 項目名 | N38: 物理名 | U38: コントロール | AB38: 必須 | AD38: 桁数 | AF38: 最大値 | AH38: 最小値 | AJ38: その他 | AN38: 方法 | AP38: 備考
B39: 『戻る』ボタン
B40: - | D40: なし | N40: - | U40: - | AB40: - | AD40: - | AF40: - | AH40: - | AJ40: - | AN40: - | BD40: Task.09

Sheet エラー画面_イベント処理
A1: プロジェクト名 | J1: システム名 | R1: 画面レイアウト設計書 | AJ1: 作成者 | AO1: 作成日 | AT1: 更新者 | AY1: 更新日
A2: =表紙!O9 -> 体験型Java研修 | J2: =表紙!O8 -> LMS学習管理システム | R2: {=MID(CELL("filename",A1),FIND("]",CELL("filename",A1))+1,FIND("_",MID(CELL("filename",A1),FIND("]",CELL("filename",A1))+2,30)))} -> エラー画面 | AJ2: 臼井 | AO2: 44265
B5: イベント処理
B7: No | D7: イベント名 | M7: イベント内容 | AV7: 備考
B8: 1 | D8: 初期表示 | M8: ①．エラー画面へ遷移
D10: コントローラー：
D11: /error
B13: 2 | D13: 『戻る』ボタン | M13: ①．ログイン画面へ遷移 | AV13: Task.09
N14: ※ログイン済の場合、自動で権限によって異なるトップ画面へリダイレクトされる
D15: コントローラー： | O15: 例）受講生の場合、コース詳細画面
D16: /

Sheet 不正アクセス_画面詳細
A1: プロジェクト名 | J1: システム名 | R1: 画面レイアウト設計書 | AJ1: 作成者 | AO1: 作成日 | AT1: 更新者 | AY1: 更新日
A2: =表紙!O9 -> 体験型Java研修 | J2: =表紙!O8 -> LMS学習管理システム | R2: {=MID(CELL("filename",A1),FIND("]",CELL("filename",A1))+1,FIND("_",MID(CELL("filename",A1),FIND("]",CELL("filename",A1))+2,30)))} -> 不正アクセス | AJ2: 臼井 | AO2: 44265
B5: 画面イメージ
B26: 画面表示項目
B27: No | D27: 項目名 | N27: データ元 | AD27: 備考 | AX27: 権限ごとの 表示可否
N28: テーブル名 | V28: フィールド | AX28: 受 | AY28: 講 | AZ28: 企 | BA28: 管 | BB28: 育
B29: 1 | D29: タイトル | N29: - | V29: - | AX29: ○ | AY29: ○
B30: 2 | D30: エラーメッセージ | N30: - | V30: - | AD30: 表示メッセージは以下の通り。 不正アクセス 不正なアクセスが検出されました。以下の行為が考えられます。 ・登録ボタンの2度押し ・URL直打ちによるアクセス ・データの不正改ざん | AX30: ○ | AY30: ○
B31: 3 | D31: 『戻る』ボタン | N31: - | V31: - | AX31: ○ | AY31: ○ | BD31: Task.09
B34: 入力パラメータ
B35: No | D35: 項目名 | N35: 物理名 | U35: コントロール | AB35: FORMクラスの入力チェック | AD35: 桁数 | AF35: 最大値 | AH35: 最小値 | AJ35: その他チェック | AN35: 送信 方法 | AP35: 備考
B36: No | D36: 項目名 | N36: 物理名 | U36: コントロール | AB36: 必須 | AD36: 桁数 | AF36: 最大値 | AH36: 最小値 | AJ36: その他 | AN36: 方法 | AP36: 備考
B37: 『戻る』ボタン
B38: - | D38: なし | N38: - | U38: - | AB38: - | AD38: - | AF38: - | AH38: - | AJ38: - | AN38: - | BD38: Task.09

Sheet 不正アクセス_イベント処理
A1: プロジェクト名 | J1: システム名 | R1: 画面レイアウト設計書 | AJ1: 作成者 | AO1: 作成日 | AT1: 更新者 | AY1: 更新日
A2: =表紙!O9 -> 体験型Java研修 | J2: =表紙!O8 -> LMS学習管理システム | R2: {=MID(CELL("filename",A1),FIND("]",CELL("filename",A1))+1,FIND("_",MID(CELL("filename",A1),FIND("]",CELL("filename",A1))+2,30)))} -> 不正アクセス | AJ2: 臼井 | AO2: 44265
B5: イベント処理
B7: No | D7: イベント名 | M7: イベント内容 | AV7: 備考
B8: 1 | D8: 初期表示 | M8: ①．不正アクセス画面へ遷移
D10: コントローラー：
D11: /illegal
B13: 2 | D13: 『戻る』ボタン | M13: ①．ログイン画面へ遷移 | AV13: Task.09
N14: ※ログイン済の場合、自動で権限によって異なるトップ画面へリダイレクトされる
D15: コントローラー： | O15: 例）受講生の場合、コース詳細画面
D16: /
