Workbook

Sheet 表紙
O8: LMS学習管理システム
O9: 体験型Java研修
S11: 共通設計
X15: ="第"&TEXT(MAX(更新履歴!A8:I167),"#0.0")&"版" -> 第1.0版 | AA15: =MAX(更新履歴!J8:Q31) -> 44265
U18: 作成者 | Z18: 審査者 | AE18: 承認者
U19: 臼井

Sheet 更新履歴
A1: プロジェクト名 | J1: システム名 | R1: 共通設計 | AJ1: 作成者 | AO1: 作成日 | AT1: 更新者 | AY1: 更新日
A2: =表紙!O9 -> 体験型Java研修 | J2: =表紙!O8 -> LMS学習管理システム | R2: 更新履歴 | AJ2: 臼井 | AO2: 44265
A5: バージョン | J5: 日付 | R5: 章番号 | V5: 内容 | AT5: 作成者 / 更新者
A8: 1 | J8: 44265 | R8: 全て | V8: 新規作成 | AT8: 臼井

Sheet 機能一覧
A1: プロジェクト名 | K1: システム名 | U1: =表紙!S11 -> 共通設計 | AO1: 作成者 | AU1: 作成日 | BA1: 更新者 | BG1: 更新日
A2: =表紙!O9 -> 体験型Java研修 | K2: =表紙!O8 -> LMS学習管理システム | U2: 機能一覧 | AO2: 臼井 | AU2: 44265
A5: No. | C5: 機能名 | U5: 画面名 | AK5: 機能詳細/備考 | BC5: 参照可能権限
BC6: 受 | BE6: 講 | BG6: 企 | BI6: 育 | BK6: 管
A7: =MAX(A$5:INDIRECT("A"&ROW()-1))+1 -> 1 | C7: ログイン機能 | U7: ログイン画面 | AK7: システムへのログインを行う際に使用。 3回連続でログインに失敗した場合はロックする。 | BC7: 〇 | BE7: 〇 | BG7: 〇 | BI7: 〇 | BK7: 〇
A8: =MAX(A$5:INDIRECT("A"&ROW()-1))+1 -> 2 | C8: パスワード再設定機能 | U8: パスワード再設定画面 | AK8: 自分自身のパスワードの再設定を行う際に使用。 | BC8: 〇 | BE8: 〇 | BG8: 〇 | BI8: 〇 | BK8: 〇
A9: =MAX(A$5:INDIRECT("A"&ROW()-1))+1 -> 3 | U9: パスワード再設定画面 | AK9: パスワードの再設定が完了した際に表示する画面。 | BC9: 〇 | BE9: 〇 | BG9: 〇 | BI9: 〇 | BK9: 〇
A10: =MAX(A$5:INDIRECT("A"&ROW()-1))+1 -> 4 | U10: パスワード再設定画面 | AK10: パスワードの再設定時にエラーが発生した際に表示する画面。 | BC10: 〇 | BE10: 〇 | BG10: 〇 | BI10: 〇 | BK10: 〇
A11: =MAX(A$5:INDIRECT("A"&ROW()-1))+1 -> 5 | C11: 企業変更機能 | U11: 企業一覧画面 | AK11: 企業の一覧を表示する画面。 企業毎にファイル共有機能を有効/無効にするかを設定する際に使用。 | BC11: × | BE11: × | BG11: × | BI11: × | BK11: 〇
A12: =MAX(A$5:INDIRECT("A"&ROW()-1))+1 -> 6 | C12: コース登録機能 | U12: コース一覧画面 | AK12: コースの一覧を表示する画面。 | BC12: × | BE12: 〇 | BG12: × | BI12: × | BK12: 〇
A13: =MAX(A$5:INDIRECT("A"&ROW()-1))+1 -> 7 | U13: コース詳細画面 | AK13: 通常コースの詳細を表示する画面。 | BC13: 〇 | BE13: 〇 | BG13: × | BI13: × | BK13: 〇
A14: =MAX(A$5:INDIRECT("A"&ROW()-1))+1 -> 8 | U14: 通常コース登録画面 | AK14: 通常コースの登録を行う画面。 | BC14: × | BE14: × | BG14: × | BI14: × | BK14: 〇
A15: =MAX(A$5:INDIRECT("A"&ROW()-1))+1 -> 9 | U15: 通常コース登録(詳細)画面 | AK15: 通常コースのカテゴリー、セクションの登録を行う画面。 | BC15: × | BE15: × | BG15: × | BI15: × | BK15: 〇
A16: =MAX(A$5:INDIRECT("A"&ROW()-1))+1 -> 10 | U16: コース概要変更画面 | AK16: 通常コースの変更を行う画面。 | BC16: × | BE16: × | BG16: × | BI16: × | BK16: 〇
A17: =MAX(A$5:INDIRECT("A"&ROW()-1))+1 -> 11 | U17: コース変更(詳細)画面 | AK17: 通常コースのカテゴリー、セクションの変更を行う画面。 | BC17: × | BE17: × | BG17: × | BI17: × | BK17: 〇
A18: =MAX(A$5:INDIRECT("A"&ROW()-1))+1 -> 12 | U18: セクション詳細画面 | AK18: セクションの詳細を表示する画面。 試験の受験や日報、週報、月報の提出、セクションに設定された教材をダウンロードする際に使用。 | BC18: 〇 | BE18: 〇 | BG18: × | BI18: × | BK18: 〇
A19: =MAX(A$5:INDIRECT("A"&ROW()-1))+1 -> 13 | C19: 開講セット出力機能 | U19: 開講セット出力画面 | AK19: 開講セットのCSV出力を行う画面。 現在は使用していない。 | BC19: × | BE19: × | BG19: × | BI19: × | BK19: 〇
A20: =MAX(A$5:INDIRECT("A"&ROW()-1))+1 -> 14 | C20: レポートテンプレート登録機能 | U20: レポート一覧画面 | AK20: 日報、週報、月報のテンプレート一覧を表示する画面。 テンプレート削除を行う際にも使用。 | BC20: × | BE20: × | BG20: × | BI20: × | BK20: 〇
A21: =MAX(A$5:INDIRECT("A"&ROW()-1))+1 -> 15 | U21: レポートテンプレート登録画面 | AK21: 日報、週報、月報のテンプレート登録を行う画面。 | BC21: × | BE21: × | BG21: × | BI21: × | BK21: 〇
A22: =MAX(A$5:INDIRECT("A"&ROW()-1))+1 -> 16 | U22: レポートテンプレート変更画面 | AK22: 日報、週報、月報のテンプレート変更を行う画面。 | BC22: × | BE22: × | BG22: × | BI22: × | BK22: 〇
A23: =MAX(A$5:INDIRECT("A"&ROW()-1))+1 -> 17 | C23: レポート提出機能 | U23: レポート一覧画面 | AK23: 提出された日報、週報、月報の一覧を表示する画面。 | BC23: × | BE23: 〇 | BG23: 〇 | BI23: 〇 | BK23: 〇
A24: =MAX(A$5:INDIRECT("A"&ROW()-1))+1 -> 18 | U24: レポート詳細画面 | AK24: 提出された日報、週報、月報の詳細を表示する画面。 フィードバックコメントの表示、登録をする際にも使用。 | BC24: 〇 | BE24: 〇 | BG24: 〇 | BI24: 〇 | BK24: 〇
A25: =MAX(A$5:INDIRECT("A"&ROW()-1))+1 -> 19 | U25: レポート提出画面 | AK25: 日報、週報、月報の提出を行う画面。 変更を行う際にも使用。 | BC25: 〇 | BE25: 〇 | BG25: × | BI25: × | BK25: 〇
A26: =MAX(A$5:INDIRECT("A"&ROW()-1))+1 -> 20 | C26: 評価レポートテンプレート登録機能 | U26: 評価レポート一覧画面 | AK26: 評価レポートのテンプレート一覧を表示する。 評価レポートのテンプレートをコピー、削除をする際にも使用。 | BC26: × | BE26: × | BG26: × | BI26: × | BK26: 〇
A27: =MAX(A$5:INDIRECT("A"&ROW()-1))+1 -> 21 | U27: 評価レポート登録画面 | AK27: 評価レポートのテンプレート登録を行う画面。 試験データ、成果物データとの紐づけを行う。 | BC27: × | BE27: × | BG27: × | BI27: × | BK27: 〇
A28: =MAX(A$5:INDIRECT("A"&ROW()-1))+1 -> 22 | U28: 評価レポート変更画面 | AK28: 評価レポートのテンプレート変更を行う画面。 試験データ、成果物データとの紐づけを変更する。 | BC28: × | BE28: × | BG28: × | BI28: × | BK28: 〇
A29: =MAX(A$5:INDIRECT("A"&ROW()-1))+1 -> 23 | C29: 評価レポート結果登録機能 | U29: 評価レポート結果登録画面 | AK29: 評価レポートの結果登録を行う画面。 評価レポートのテンプレートに応じて登録する。 | BC29: × | BE29: 〇 | BG29: × | BI29: × | BK29: 〇
A30: =MAX(A$5:INDIRECT("A"&ROW()-1))+1 -> 24 | C30: 評価レポート採点確認機能 | U30: 評価レポート採点確認画面 | AK30: 評価レポートをCSVを用い一括出力、一括採点する際に使用。 | BC30: × | BE30: 〇 | BG30: × | BI30: × | BK30: 〇
A31: =MAX(A$5:INDIRECT("A"&ROW()-1))+1 -> 25 | C31: 評価レポート公開機能、評価レポートダウンロード機能 | U31: 評価レポート一覧画面 | AK31: 評価レポートの採点状況の確認、並びに公開を行う際に使用。 | BC31: × | BE31: × | BG31: × | BI31: × | BK31: 〇
A32: =MAX(A$5:INDIRECT("A"&ROW()-1))+1 -> 26 | C32: 試験問題登録機能 | U32: 試験カテゴリー一覧画面 | AK32: 試験カテゴリーの一覧を表示する画面。 詳細試験カテゴリーを削除をする際にも使用。 | BC32: × | BE32: × | BG32: × | BI32: × | BK32: 〇
A33: =MAX(A$5:INDIRECT("A"&ROW()-1))+1 -> 27 | U33: 試験カテゴリー登録画面 | AK33: 試験カテゴリーの登録を行う画面。 | BC33: × | BE33: × | BG33: × | BI33: × | BK33: 〇
A34: =MAX(A$5:INDIRECT("A"&ROW()-1))+1 -> 28 | U34: 試験カテゴリー変更画面 | AK34: 試験カテゴリーの変更を行う画面。 | BC34: × | BE34: × | BG34: × | BI34: × | BK34: 〇
A35: =MAX(A$5:INDIRECT("A"&ROW()-1))+1 -> 29 | U35: 詳細試験カテゴリー登録画面 | AK35: 詳細試験カテゴリー登録を行う画面。 | BC35: × | BE35: × | BG35: × | BI35: × | BK35: 〇
A36: =MAX(A$5:INDIRECT("A"&ROW()-1))+1 -> 30 | U36: 詳細試験カテゴリー変更画面 | AK36: 詳細試験カテゴリー変更を行う画面。 | BC36: × | BE36: × | BG36: × | BI36: × | BK36: 〇
A37: =MAX(A$5:INDIRECT("A"&ROW()-1))+1 -> 31 | U37: 試験登録画面 | AK37: 試験の登録を行う画面。 | BC37: × | BE37: × | BG37: × | BI37: × | BK37: 〇
A38: =MAX(A$5:INDIRECT("A"&ROW()-1))+1 -> 32 | U38: 試験問題登録画面 | AK38: 試験の問題登録を行う画面。 | BC38: × | BE38: × | BG38: × | BI38: × | BK38: 〇
A39: =MAX(A$5:INDIRECT("A"&ROW()-1))+1 -> 33 | U39: 試験内容変更画面 | AK39: 試験の内容変更を行う画面。 試験名や制限時間等を変更する際に使用。 | BC39: × | BE39: × | BG39: × | BI39: × | BK39: 〇
A40: =MAX(A$5:INDIRECT("A"&ROW()-1))+1 -> 34 | U40: 試験問題変更画面 | AK40: 試験の問題変更を行う。 試験の問題数の変更は出来ない。 | BC40: × | BE40: × | BG40: × | BI40: × | BK40: 〇
A41: =MAX(A$5:INDIRECT("A"&ROW()-1))+1 -> 35 | U41: 試験一覧画面 | AK41: 試験の一覧を表示する画面。 試験を削除する際にも使用。 | BC41: × | BE41: 〇 | BG41: 〇 | BI41: 〇 | BK41: 〇
A42: =MAX(A$5:INDIRECT("A"&ROW()-1))+1 -> 36 | U42: 試験詳細画面 | AK42: 試験の詳細を表示する画面。 | BC42: 〇 | BE42: 〇 | BG42: 〇 | BI42: 〇 | BK42: 〇
...

Sheet メッセージ一覧
A1: プロジェクト名 | J1: システム名 | R1: =表紙!S11 -> 共通設計 | AJ1: 作成者 | AO1: 作成日 | AT1: 更新者 | AY1: 更新日
A2: =表紙!O9 -> 体験型Java研修 | J2: =表紙!O8 -> LMS学習管理システム | R2: メッセージ一覧 | AJ2: 臼井 | AO2: 44265
A5: No. | C5: メッセージID | M5: メッセージ内容 | AK5: 備考 | AP5: 備考
A6: =MAX(A$5:INDIRECT("A"&ROW()-1))+1 -> 1 | C6: mail.contract.subject | M6: 【東京ITスクール】ご契約内容の送付
A7: =MAX(A$5:INDIRECT("A"&ROW()-1))+1 -> 2 | C7: mail.contract.body | M7: お世話になっております。\n\n株式会社システムシェアード\n東京ITスクール運営事務局でございます。 \n\n以下の内容で契約を締結致しました。\nご確認頂きます様お願い致します。\n\n【契約内容】\n:contract:\n\n【個人情報利用目的】\n:personal:\n\n※このメールにお心当たりがない場合はご破棄くださいますようお願い致します。\n※このメールはサーバより自動送信しておりますため、ご返信頂いてもお答えできません。\nお問い合わせは、itsup@3sss.co.jpまでお願い致します。
A8: =MAX(A$5:INDIRECT("A"&ROW()-1))+1 -> 3 | C8: mail.resetpass.subject | M8: 【LMS学習管理システム】パスワード再設定手続きのお知らせ
A9: =MAX(A$5:INDIRECT("A"&ROW()-1))+1 -> 4 | C9: mail.resetpass.body | M9: LMSをご利用いただきありがとうございます。\n\nユーザのパスワード変更を受け付けました。\n下記URLにアクセス後、新規にパスワードを設定してください。\n\n:url:\n\n※このメールにお心当たりがない場合はご破棄くださいますようお願い致します。\n※このメールはサーバより自動送信しておりますため、ご返信頂いてもお答えできません。\nお問い合わせは、itsup@3sss.co.jpまでお願い致します。
A10: =MAX(A$5:INDIRECT("A"&ROW()-1))+1 -> 5 | C10: mail.logininfo.subject | M10: 【LMS学習管理システム】ログイン情報の送付
A11: =MAX(A$5:INDIRECT("A"&ROW()-1))+1 -> 6 | C11: mail.logininfo.body | M11: LMSをご利用いただきありがとうございます。\nログイン情報を発行しました。以下の認証情報を利用してログインしてください。\n\nLMS学習管理システムURL：:url:\nログインID：:login_id:\nパスワード：:password:\n\n※このメールにお心当たりがない場合はご破棄くださいますようお願い致します。\n※このメールはサーバより自動送信しておりますため、ご返信頂いてもお答えできません。\nお問い合わせは、itsup@3sss.co.jpまでお願い致します。
A12: =MAX(A$5:INDIRECT("A"&ROW()-1))+1 -> 7 | C12: mail.mailfailed.subject | M12: 【LMS】メールの送信に失敗しています。
A13: =MAX(A$5:INDIRECT("A"&ROW()-1))+1 -> 8 | C13: mail.mailfailed.body | M13: LMSをご利用いただきありがとうございます。\n\nメールの送信に失敗しているデータがあります。\nシステム管理者にお問い合わせください。\n\nメールアドレス：:mail_address:\n件名：:subject:\n送信予約日時：:que_create_date:\n\n※このメールにお心当たりがない場合はご破棄くださいますようお願い致します。\n※このメールはサーバより自動送信しておりますため、ご返信頂いてもお答えできません。\nお問い合わせは、itsup@3sss.co.jpまでお願い致します。
A14: =MAX(A$5:INDIRECT("A"&ROW()-1))+1 -> 9 | C14: attendance.update.notice | M14: 勤怠情報の登録が完了しました。
A15: =MAX(A$5:INDIRECT("A"&ROW()-1))+1 -> 10 | C15: attendance.company.joseiKinInfoIsNotExists | M15: 対象ユーザの企業は助成金情報が未入力のため、画面を表示することができません。
A16: =MAX(A$5:INDIRECT("A"&ROW()-1))+1 -> 11 | C16: regist.complete | M16: {0}の登録が完了しました。
A17: =MAX(A$5:INDIRECT("A"&ROW()-1))+1 -> 12 | C17: update.complete | M17: {0}の更新が完了しました。
... A35: =MAX(A$5:INDIRECT("A"&ROW()-1))+1 -> 30 | C35: fileShare.fileShareFlg | M35: 貴社はファイル共有機能の使用が許可されていません。

Sheet エラーメッセージ一覧
A1: プロジェクト名 | J1: システム名 | R1: =表紙!S11 -> 共通設計 | AJ1: 作成者 | AO1: 作成日 | AT1: 更新者 | AY1: 更新日
A2: =表紙!O9 -> 体験型Java研修 | J2: =表紙!O8 -> LMS学習管理システム | R2: メッセージ一覧 | AJ2: 臼井 | AO2: 44265
A5: No. | C5: メッセージID | M5: メッセージ内容 | AK5: 備考 | AP5: 備考
A6: =MAX(A$5:INDIRECT("A"&ROW()-1))+1 -> 1 | C6: header | M6: <ul style="padding-left:0;list-style:none;">
A7: =MAX(A$5:INDIRECT("A"&ROW()-1))+1 -> 2 | C7: footer | M7: </ul>
A8: =MAX(A$5:INDIRECT("A"&ROW()-1))+1 -> 3 | C8: prefix | M8: <li><span class="help-inline error">*&nbsp;
A9: =MAX(A$5:INDIRECT("A"&ROW()-1))+1 -> 4 | C9: suffix | M9: </span></li>
A10: =MAX(A$5:INDIRECT("A"&ROW()-1))+1 -> 5 | C10: invalid | M10: {0}が不正です。
A11: =MAX(A$5:INDIRECT("A"&ROW()-1))+1 -> 6 | C11: maxlength | M11: {0}の長さが最大値({1})を超えています。
A12: =MAX(A$5:INDIRECT("A"&ROW()-1))+1 -> 7 | C12: minlength | M12: {0}の長さが最小値({1})未満です。
A13: =MAX(A$5:INDIRECT("A"&ROW()-1))+1 -> 8 | C13: maxval | M13: {0}の値が最大値({1})を超えています。
A14: =MAX(A$5:INDIRECT("A"&ROW()-1))+1 -> 9 | C14: maxvalBulk | M14: {0}：{1}が最大値({2})を超えています。
A15: =MAX(A$5:INDIRECT("A"&ROW()-1))+1 -> 10 | C15: minval | M15: {0}の値が最小値({1})未満です。
A16: =MAX(A$5:INDIRECT("A"&ROW()-1))+1 -> 11 | C16: maxbytelength | M16: {0}のバイト長が最大値({1})を超えています。
A17: =MAX(A$5:INDIRECT("A"&ROW()-1))+1 -> 12 | C17: minbytelength | M17: {0}のバイト長が最小値({1})未満です。
... A157: =MAX(A$5:INDIRECT("A"&ROW()-1))+1 -> 152 | C157: evReport.csvUpload.emptyDeliverablesResult | M157: {0}行目の{1}は提出されていません。点数を入力しないで入力してください。

Sheet エラーメッセージ一覧（入力チェック）
A1: プロジェクト名 | J1: システム名 | R1: =表紙!S11 -> 共通設計 | AJ1: 作成者 | AO1: 作成日 | AT1: 更新者 | AY1: 更新日
A2: =表紙!O9 -> 体験型Java研修 | J2: =表紙!O8 -> LMS学習管理システム | R2: メッセージ一覧 | AJ2: 臼井 | AO2: 44265
A5: No. | C5: メッセージID | M5: メッセージ内容 | AK5: 備考 | AP5: 備考
A6: =MAX(A$5:INDIRECT("A"&ROW()-1))+1 -> 1 | C6: javax.validation.constraints.NotBlank.message | M6: {0}は必須です。
A7: =MAX(A$5:INDIRECT("A"&ROW()-1))+1 -> 2 | C7: javax.validation.constraints.Size.message | M7: {0}の長さが最大値({max})を超えています。
A8: =MAX(A$5:INDIRECT("A"&ROW()-1))+1 -> 3 | C8: javax.validation.constraints.Max.message | M8: {0}の値が最大値({1})を超えています。
A9: =MAX(A$5:INDIRECT("A"&ROW()-1))+1 -> 4 | C9: javax.validation.constraints.Min.message | M9: {0}の値が最小値({1})未満です。
A10: =MAX(A$5:INDIRECT("A"&ROW()-1))+1 -> 5 | C10: pattern.outRangeNumber | M10: {0}は、半角数字で、{1}～{2}の範囲内で入力してください。
A11: =MAX(A$5:INDIRECT("A"&ROW()-1))+1 -> 6 | C11: javax.validation.constraints.Email.message | M11: {0}はメールアドレスとして不正です。
A12: =MAX(A$5:INDIRECT("A"&ROW()-1))+1 -> 7 | C12: pattern.password | M12: 「パスワード」には半角英数字のみ使用可能です。また、半角英大文字、半角英小文字、数字を含めた8～20文字を入力してください。

Sheet ラベル一覧
A1: プロジェクト名 | J1: システム名 | R1: =表紙!S11 -> 共通設計 | AJ1: 作成者 | AO1: 作成日 | AT1: 更新者 | AY1: 更新日
A2: =表紙!O9 -> 体験型Java研修 | J2: =表紙!O8 -> LMS学習管理システム | R2: ラベル一覧 | AJ2: 臼井 | AO2: 44265
A5: No. | C5: ラベルID | M5: ラベル内容 | AK5: 備考 | AP5: 備考
A6: =MAX(A$5:INDIRECT("A"&ROW()-1))+1 -> 1 | C6: user | M6: ユーザー
A7: =MAX(A$5:INDIRECT("A"&ROW()-1))+1 -> 2 | C7: lmsUser | M7: ユーザー
A8: =MAX(A$5:INDIRECT("A"&ROW()-1))+1 -> 3 | C8: company | M8: 企業
A9: =MAX(A$5:INDIRECT("A"&ROW()-1))+1 -> 4 | C9: userCompany | M9: 送信先の企業担当者
A10: =MAX(A$5:INDIRECT("A"&ROW()-1))+1 -> 5 | C10: companyData | M10: 企業データ
A11: =MAX(A$5:INDIRECT("A"&ROW()-1))+1 -> 6 | C11: place | M11: 会場
A12: =MAX(A$5:INDIRECT("A"&ROW()-1))+1 -> 7 | C12: course | M12: コース
A13: =MAX(A$5:INDIRECT("A"&ROW()-1))+1 -> 8 | C13: section | M13: セクション
A14: =MAX(A$5:INDIRECT("A"&ROW()-1))+1 -> 9 | C14: category | M14: カテゴリ
A15: =MAX(A$5:INDIRECT("A"&ROW()-1))+1 -> 10 | C15: genre | M15: 試験カテゴリ
A16: =MAX(A$5:INDIRECT("A"&ROW()-1))+1 -> 11 | C16: genre.detail | M16: 詳細試験カテゴリ
A17: =MAX(A$5:INDIRECT("A"&ROW()-1))+1 -> 12 | C17: exam | M17: 試験
... A258: =MAX(A$5:INDIRECT("A"&ROW()-1))+1 -> 253 | C258: evReport.detail.deliverablesField | M258: 成果物項目
